Workbook

Sheet Cadastro Geral Campistas
A1: FICHA | B1: NOME | C1: TAMANHO DA CAMISETA | D1: SEXO | E1: PESO | F1: ALTURA | G1: IDADE | H1: CELULAR | I1: CIDADE | J1: CONFLITOS / CONHECIDOS | K1: NOMES CONTATOS I | L1: TELEFONE CONTATO I | M1: NOMES CONTATOS II | N1: TELEFONE CONTATO II | O1: ALERGIAS | P1: DATA DE NASCIMENTO | Q1: TRIBO | R1: PARCEIRO FC
A2: 1 | B2: Adejar Nunes Guimarães | C2: G | D2: M | E2: 73 | F2: 1.66 | G2: 74 | H2: +55 (64) 98408-2025 | I2: Caçu | J2: Sim. Eliete Fátima (esposa), Catarina Elzi (conhecida) | K2: Geovana Guimarães | L2: 62982185298 | M2: Thaís Guimarães | N2: 62982185297 | O2: Não que eu saiba | P2: 1952-04-03 | Q2: Benjamim
A3: 2 | B3: Affonso Moreira Cardoso | C3: M | D3: M | E3: 75 | F3: 1.65 | G3: 39 | H3: +55 (62) 98279-1421 | I3: Goiania | J3: Não | K3: Raquel irmã | L3: +55 62 8270-9532 | M3: Mônica mãe | N3: 0 62 8114-5127 | O3: Não | P3: 1986-12-26 | Q3: Rubem
A4: 3 | B4: Aires Silva | C4: G | D4: M | E4: 82 | F4: 1.75 | G4: 62 | H4: +55 (62) 99159-4335 | I4: Goiânia | J4: Sim. Maria Ivone (esposa) | K4: Ana Paula | L4: (11) 93321-1010 | M4: Ana Gabriela | N4: (62) 992747297 | O4: Frutos do mar | P4: 1964-02-01 | Q4: Levi | R4: 100
A5: 4 | B5: Amanda Werneck | C5: G | D5: F | E5: 69 | F5: 1.7 | G5: 45 | H5: +55 (62) 99804-9912 | I5: Goiânia | J5: Não. | K5: Luiz Botosso | L5: 62996037374 | M5: Luiza Werneck | N5: 6299808079 | O5: Insetos | P5: 1980-07-23 | Q5: Simeão
A6: 5 | B6: Amarildo Ferreira | C6: G | D6: M | E6: 85 | F6: 1.72 | G6: 36 | H6: +55 (61) 99571-6653 | I6: Goiânia | J6: Alexandre | K6: Ubiratan | L6: 62981576273 | M6: Amanda | N6: 6181708411 | O6: não | P6: 1989-05-25 | Q6: Judá
A7: 6 | B7: Ana Gabriela Borges Teixeira | C7: P | D7: F | E7: 60 | F7: 1.68 | G7: 26 | H7: +55 (91) 98207-7079 | I7: Goiânia | J7: Não | K7: Stella Borges | L7: 62 98182-3358 | M7: Monique Borges | N7: 62 98244-1695 | O7: Não | P7: 1999-11-14 | Q7: Simeão
A8: 7 | B8: Ana Gabriela Franco Ribeiro Aguiar | C8: P | D8: F | E8: 59 | F8: 1.55 | G8: 44 | H8: +55 (62) 98626-6626 | I8: Goiânia | J8: Não | K8: Gisele | L8: 62 98114-5347 | M8: Bruno | N8: 62 98466-6695 | O8: Sim, abelhas | P8: 1981-07-17 | Q8: EFRAIM | R8: 16
A9: 8 | B9: Ana Luiza Gonçalves Bueno | C9: G | D9: F | E9: 70 | F9: 1.64 | G9: 53 | H9: +55 (01) 56298-1816 | I9: Goiana | J9: Fabiano Pereira | K9: Fernanda | L9: (061) 99270-5252 | M9: Luciano | N9: (061) 98431-9558 | O9: Não | P9: 1973-01-21 | Q9: Judá | R9: 40
A10: 9 | B10: Ana Luiza Vaz Carvalho | C10: M | D10: F | E10: 59 | F10: 1.63 | G10: 27 | H10: +55 (62) 99321-9967 | I10: Goiânia | J10: Julia Jayme. Foi da minha turma de faculdade. | K10: Marlene de Oliveira Vaz Carvalho | L10: 62981549705 | M10: Elivar Antonio de Carvalho | N10: 62981654656 | O10: Não | P10: 1998-05-19 | Q10: Zabulom
A11: 10 | B11: Anna Clara Silva Guimarães | C11: P | D11: F | E11: 50 | F11: 1.5 | G11: 22 | H11: +55 (62) 99325-0970 | I11: Goiânia | J11: Luara Couto | K11: Marcos Augusto | L11: 62984467506 | M11: Camila | N11: 62993889308 | O11: Não | P11: 2003-05-15 | Q11: Judá
A12: 11 | B12: Antônio Francisco de Oliveira | C12: G | D12: M | E12: 86 | F12: 1.78 | G12: 52 | H12: +55 (62) 98561-2097 | I12: Goiânia | J12: Não | K12: Marciella - minha esposa (62) 98424-2802 | L12: (62) 98424-2802 | M12: Gustavo Henrique - Meu filho (62) 99685-0807 | N12: (62) 99685-0807 | O12: Não | P12: 1973-09-18 | Q12: Judá
A13: 12 | B13: Ariane Dias da Luz | C13: M | D13: F | E13: 72 | F13: 1.65 | G13: 30 | H13: +55 (62) 98237-5037 | I13: Aparecida de Goiania | J13: Sim Marcos Felipe | K13: Ciane | L13: 62 982353865 | M13: Tuana | N13: 62 9 98080605 | O13: Nao | P13: 1995-11-19 | Q13: Zabulom | R13: 92
A14: 13 | B14: Augustinho Severino da Cruz | C14: G | D14: M | E14: 84 | F14: 1.8 | G14: 60 | H14: +55 (63) 92844-486 | I14: Paranã | J14: sim | K14: Vinicius Roberto Da Cruz | L14: 64996480435 | M14: Eneida Alexo Silva Cruz | N14: +55 63 8490-7234 | O14: não | P14: 1965-08-30 | Q14: Zabulom
A15: 14 | B15: Bruna Amaral Martins | C15: P | D15: F | E15: 60 | F15: 1.64 | G15: 26 | H15: +55 (62) 99908-1082 | I15: Goiânia | J15: Eliane Martins Nunes (mãe) | K15: Eliane | L15: 62999711082 | M15: Sérgio | N15: 6296968688 | O15: Não | P15: 2000-03-22 | Q15: EFRAIM
A16: 15 | B16: Bruna Tayssa Rockenbach Padilha | C16: G | D16: F | E16: 80 | F16: 1.75 | G16: 33 | H16: +55 (66) 98446-8785 | I16: Canarana | J16: Sim meu esposo, Raul. | K16: Camila Padilha | L16: 66.9.96215646 | M16: Franciele Passold | N16: 66.9.92076690 | O16: Não | P16: 1992-07-15 | Q16: Judá
A17: 16 | B17: Bruno Aguiar | C17: G | D17: M | E17: 85 | F17: 1.86 | G17: 43 | H17: +55 (62) 98466-6696 | I17: Goiânia | J17: Não | K17: Bernard | L17: 62 99857-6666 | M17: Beatriz | N17: 62 99614-7908 | O17: Não | P17: 1982-06-19 | Q17: Benjamim | R17: 7
A18: 17 | B18: Caio Rabelo da Silva Furtado | C18: M | D18: M | E18: 64 | F18: 1.84 | G18: 22 | H18: +55 (62) 99524-6943 | I18: Aparecida de Goiânia | J18: Não | K18: Flávia (mãe) | L18: 62 992234808 | M18: Ronaldo (Pai) | N18: 62 992420035 | O18: Não | P18: 2004-02-10 | Q18: Judá
A19: 18 | B19: Carla Rodrigues Ferreira | C19: P | D19: F | E19: 60 | F19: 1.65 | G19: 46 | H19: +55 (62) 98325-7488 | I19: Goiânia | J19: Não | K19: Carolline Rodrigues | L19: (62) 98145 1313 | M19: Camila Rodrigues | N19: (62) 98452 5353 | O19: Não | P19: 1979-08-06 | Q19: Gad
A20: 19 | B20: Carlos Bruno Rodrigues | C20: GG | D20: M | E20: 89 | F20: 1.78 | G20: 49 | H20: +55 (62) 99639-1240 | I20: Goiânia | J20: esposa Karla Regina da Silva Rodrigues | K20: Giovanna | L20: 62999518515 | M20: Gabriella | N20: 62992448557 | O20: não | P20: 1976-05-27 | Q20: Simeão | R20: 71
A21: 20 | B21: Carlos euripedes Tavares | C21: M | D21: M | E21: 70 | F21: 1.6 | G21: 71 | H21: +55 (62) 99844-3069 | I21: Goiânia | J21: Não | K21: Leandro | L21: 62-999756864 | M21: Juliana 999756678 | N21: 62-999756678 | O21: Não | P21: 1954-09-10 | Q21: Benjamim
A22: 21 | B22: Carlos Henrique de Souza Dourado | C22: GG | D22: M | E22: 100 | F22: 1.79 | G22: 32 | H22: +55 (62) 99461-5119 | I22: Goianira | J22: Não | K22: Carlos Cesar de Souza Dourado | L22: 62985200025 | M22: Julio Wanderson | N22: 62996329737 | O22: Não | P22: 1994-02-24 | Q22: Levi | R22: 105
A23: 22 | B23: Cassiano Resende | C23: GG | D23: M | E23: 89 | F23: 1.75 | G23: 36 | H23: +55 (62) 98500-0392 | I23: Mairipotaba | J23: Fabricio Michel | K23: Fabricio Michel | L23: 62985000392 | M23: Renilda Pereira | N23: +32 476 59 39 22 | O23: Não | P23: 1989-07-22 | Q23: Rubem
A24: 23 | B24: Catarina Elzi de Oliveira | C24: G | D24: F | E24: 70 | F24: 1.56 | G24: 72 | H24: +55 (34) 99902-0453 | I24: Jussara | J24: Sim. Eliete e Adejar. | K24: Geovana Guimarães de Oliveira | L24: 62982185298 | M24: Thaís Guimarães de Oliveira | N24: 62982185297 | O24: Que saiba não | P24: 1953-10-04 | Q24: Issacar
A25: 24 | B25: Celma Maria de Queiroz Silva | C25: M | D25: F | E25: 70 | F25: 1.67 | G25: 66 | H25: +55 (62) 98208-2395 | I25: Goiânia | J25: Não | K25: Rodrigo Queiroz | L25: 62 9 9614-2740 | M25: Jonas Manoel | N25: 62 9 8328-5140 | O25: Alergia a Sulfa e Penicilina | P25: 1959-08-24 | Q25: Rubem
A26: 25 | B26: Charles Juliano Visconti | C26: GG | D26: M | E26: 86 | F26: 1.78 | G26: 49 | H26: +55 (66) 99911-3161 | I26: Canarana | J26: Não | K26: Staney | L26: 66 999888998 | M26: Shirlei | N26: 47 999834854 | O26: Não | P26: 1976-07-29 | Q26: Gad
A27: 26 | B27: CIRILO DE JESUS SOARES | C27: G | D27: M | E27: 95 | F27: 1.75 | G27: 46 | H27: +55 (62) 99922-2008 | I27: Goiânia | J27: Luciana Costa de Oliveira Soares | K27: Maria Aparecida | L27: 62993997089 | M27: Pedro Henrique | N27: 62994000079 | O27: Não | P27: 1980-03-18 | Q27: EFRAIM | R27: 82
A28: 27 | B28: CLEONIS Pereira de Castro | C28: G | D28: M | E28: 78 | F28: 1.72 | G28: 66 | H28: +55 (62) 99958-1174 | I28: Goiânia | J28: Sim | K28: Iraci | L28: 62996745312 | M28: Larissa | N28: 62999765788 | O28: Não | P28: 2059-10-14 | Q28: Simeão
A29: 28 | B29: cley Altair santos | C29: G | D29: M | E29: 84 | F29: 1.77 | G29: 48 | H29: +55 (62) 99404-2763 | I29: Goiânia | J29: não | K29: filho João Vitor | L29: 6295457305 | M29: mãe celeste | N29: 6281593412 | O29: não | P29: 1977-05-16 | Q29: Issacar
A30: 29 | B30: CLEYTA FERREIRA DO COUTO | C30: G1 | D30: F | E30: 120 | F30: 1.71 | G30: 44 | H30: +55 (62) 99808-5175 | I30: Goiânia | J30: não | K30: Marido - Fernando | L30: (62) 99307-9547 | M30: Pai - Sebastião | N30: (62) 99611-5175 | O30: camarão, amendoin, coco, pelo de cachorro. | P30: 1981-09-21 | Q30: Judá
A31: 30 | B31: Diego Francisco dos Santos | C31: G | D31: M | E31: 79 | F31: 1.76 | G31: 31 | H31: +55 (62) 99201-8512 | I31: Goiânia | J31: Nao | K31: Daniel | L31: 62985630030 | M31: Daniel | N31: 62985630030 | O31: Nao | P31: 1994-11-29 | Q31: Levi
A32: 31 | B32: Diego Grando | C32: M | D32: M | E32: 78 | F32: 1.79 | G32: 43 | H32: +55 (49) 99912-1598 | I32: Pinhalzinho SC | J32: Josiane fiorini | K32: marise Grando | L32: 49 999834653 | M32: Marise Grando | N32: 49 999834653 | O32: não | P32: 1982-07-25 | Q32: Issacar
A33: 32 | B33: Dirce de Souza Lobo Oliveira | C33: M | D33: F | E33: 70 | F33: 1.65 | G33: 57 | H33: +55 (62) 99647-4797 | I33: Pires do Rio | J33: Donizete Antonio de Oliveira - Meu marido | K33: Dayanne Oliveira | L33: 62999675342 | M33: Danielly Oliveira | N33: 62996026126 | O33: Não | P33: 1969-02-22 | Q33: Rubem | R33: 33
A34: 33 | B34: Donizete Antonio de Oliveira | C34: G | D34: M | E34: 95 | F34: 1.68 | G34: 63 | H34: +55 (62) 99661-4603 | I34: Vianópolis/Pires do Rio | J34: Dirce Lobo/ Vânia Oliveira/ Nilson Oliveira | K34: danielly | L34: 62999675352 | M34: dayanne | N34: 62996026126 | O34: não | P34: 1963-04-06 | Q34: Benjamim | R34: 32
A35: 34 | B35: eder ribeiro da silva | C35: M | D35: M | E35: 75 | F35: 1.72 | G35: 43 | H35: +55 (62) 99699-2468 | I35: goiania | J35: nao | K35: esposa vanessa | L35: 62998079634 | M35: filho richard | N35: 62996992468 | O35: nao | P35: 1982-07-14 | Q35: Issacar
A36: 35 | B36: EDMAR DE PAULA SILVA | C36: GG | D36: M | E36: 87 | F36: 1.75 | G36: 39 | H36: +55 (16) 99755-3271 | I36: FRANCA SP | J36: NÃO | K36: GILBERTO (IRMÃO) | L36: 6299769578 | M36: ALINE (IRMÃ) | N36: 1699989-0819 | O36: NAO | P36: 1987-01-26 | Q36: Judá
A37: 36 | B37: Edson Luiz Pacheco Junior | C37: G | D37: M | E37: 85 | G37: 25 | H37: +55 (62) 99477-9724 | I37: Goiânia | J37: esposa Sara Angel, amigos: Josane, Pedro Luan, e Thais (está na reserva) | K37: sogra Jackeline | L37: 62 99117-1714 somente WhatsApp | M37: tia Suely | N37: 62 99292-3030 | O37: intolerância a lactose | P37: 2000-08-31 | Q37: Rubem
A38: 37 | B38: ELIANE MARTINS NUNES | C38: M | D38: F | E38: 66 | F38: 1.61 | G38: 60 | H38: +55 (62) 99971-1082 | I38: GOIÂNIA | J38: Não | K38: BRUNA | L38: 62 99908.1082 | M38: SÉRGIO | N38: 62 99696.8688 | O38: Não | P38: 1965-06-04 | Q38: Zabulom
A39: 38 | B39: Eliete Fátima Guimarães | C39: M | D39: F | E39: 58 | F39: 1.55 | G39: 68 | H39: +55 (64) 98431-2836 | I39: Caçu | J39: Sim. Adejar (marido) e Catarina Elzi (conhecida) | K39: Geovana Guimarães | L39: 62982185298 | M39: Thaís Guimarães | N39: 62982185297 | O39: Não que eu saiba | P39: 1957-09-06 | Q39: Gad
A40: 39 | B40: Elisvania Maria de Oliveira Silva | C40: G | D40: F | E40: 78 | G40: 49 | H40: +55 (62) 99937-9138 | I40: Vianopolis | J40: Não! | K40: Lara Caixeta | L40: 62999413446 | M40: João Antônio Oliveira Silva | N40: 62999482791 | O40: Não | P40: 1976-11-22 | Q40: Judá
...

Sheet Relatorio Familia Provas
A1: Cor: Amarela | E1: Tribo Simeão
A4: Anjos: | G4: Anjo Guardião:
A5: Bruno Cunha | G5: Ericka
A6: Suellen
A8: Ficha ✏️ | B8: Nome | C8: Peso | D8: Alt | E8: Idade | F8: Cidade | G8: Camiseta | H8: Celular | I8: ⚠️ Alerta / Observações | J8: Sexo
A9: 4 | B9: =IFERROR(VLOOKUP(A9,'Cadastro Geral Campistas'!$A:$R,2,0),"") | C9: =IFERROR(VLOOKUP(A9,'Cadastro Geral Campistas'!$A:$R,5,0),"") | D9: =IFERROR(VLOOKUP(A9,'Cadastro Geral Campistas'!$A:$R,6,0),"") | E9: =IFERROR(VLOOKUP(A9,'Cadastro Geral Campistas'!$A:$R,7,0),"") | F9: =IFERROR(VLOOKUP(A9,'Cadastro Geral Campistas'!$A:$R,9,0),"") | G9: =IFERROR(VLOOKUP(A9,'Cadastro Geral Campistas'!$A:$R,3,0),"") | H9: =IFERROR(VLOOKUP(A9,'Cadastro Geral Campistas'!$A:$R,8,0),"") | I9: =IF(AND(IFERROR(VLOOKUP(A9,'Cadastro Geral Campistas'!$A:$R,18,0),0)>0,COUNTIF($A$9:$A$24,IFERROR(VLOOKUP(A9,'Cadastro Geral Campistas'!$A:$R,18,0),0))>0),"⚠️ CONFLITO! Cônjuge na mesma tribo: "&IFERROR(VLOOKUP(IFERROR(VLOOKUP(A9,'Cadastro Geral Campistas'!$A:$R,18,0),0),'Cadastro Geral Campistas'!$A:$R,2,""),""),TRIM(IF(AND(IFERROR(VLOOKUP(A9,'Cadastro Geral Campistas'!$A:$R,10,0),"")<>"",LOWER(TRIM(IFERROR(VLOOKUP(A9,'Cadastro Geral Campistas'!$A:$R,10,0),"")))<>"não",LOWER(TRIM(IFERROR(VLOOKUP(A9,'Cadastro Geral Campistas'!$A:$R,10,0),"")))<>"nao",LOWER(TRIM(IFERROR(VLOOKUP(A9,'Cadastro Geral Campistas'!$A:$R,10,0),"")))<>"0"),IFERROR(VLOOKUP(A9,'Cadastro Geral Campistas'!$A:$R,10,0),"")&IF(AND(IFERROR(VLOOKUP(A9,'Cadastro Geral Campistas'!$A:$R,15,0),"")<>"",LOWER(TRIM(IFERROR(VLOOKUP(A9,'Cadastro Geral Campistas'!$A:$R,15,0),"")))<>"não",LOWER(TRIM(IFERROR(VLOOKUP(A9,'Cadastro Geral Campistas'!$A:$R,15,0),"")))<>"nao",LOWER(TRIM(IFERROR(VLOOKUP(A9,'Cadastro Geral Campistas'!$A:$R,15,0),"")))<>"0")," | Alergia: "&IFERROR(VLOOKUP(A9,'Cadastro Geral Campistas'!$A:$R,15,0),""),""),IF(AND(IFERROR(VLOOKUP(A9,'Cadastro Geral Campistas'!$A:$R,15,0),"")<>"",LOWER(TRIM(IFERROR(VLOOKUP(A9,'Cadastro Geral Campistas'!$A:$R,15,0),"")))<>"não",LOWER(TRIM(IFERROR(VLOOKUP(A9,'Cadastro Geral Campistas'!$A:$R,15,0),"")))<>"nao",LOWER(TRIM(IFERROR(VLOOKUP(A9,'Cadastro Geral Campistas'!$A:$R,15,0),"")))<>"0"),"Alergia: "&IFERROR(VLOOKUP(A9,'Cadastro Geral Campistas'!$A:$R,15,0),""),"")))) | J9: =IFERROR(VLOOKUP(A9,'Cadastro Geral Campistas'!$A:$R,4,0),"")
A10: 6 | B10: =IFERROR(VLOOKUP(A10,'Cadastro Geral Campistas'!$A:$R,2,0),"") | C10: =IFERROR(VLOOKUP(A10,'Cadastro Geral Campistas'!$A:$R,5,0),"") | D10: =IFERROR(VLOOKUP(A10,'Cadastro Geral Campistas'!$A:$R,6,0),"") | E10: =IFERROR(VLOOKUP(A10,'Cadastro Geral Campistas'!$A:$R,7,0),"") | F10: =IFERROR(VLOOKUP(A10,'Cadastro Geral Campistas'!$A:$R,9,0),"") | G10: =IFERROR(VLOOKUP(A10,'Cadastro Geral Campistas'!$A:$R,3,0),"") | H10: =IFERROR(VLOOKUP(A10,'Cadastro Geral Campistas'!$A:$R,8,0),"") | I10: =IF(AND(IFERROR(VLOOKUP(A10,'Cadastro Geral Campistas'!$A:$R,18,0),0)>0,COUNTIF($A$9:$A$24,IFERROR(VLOOKUP(A10,'Cadastro Geral Campistas'!$A:$R,18,0),0))>0),"⚠️ CONFLITO! Cônjuge na mesma tribo: "&IFERROR(VLOOKUP(IFERROR(VLOOKUP(A10,'Cadastro Geral Campistas'!$A:$R,18,0),0),'Cadastro Geral Campistas'!$A:$R,2,""),""),TRIM(IF(AND(IFERROR(VLOOKUP(A10,'Cadastro Geral Campistas'!$A:$R,10,0),"")<>"",LOWER(TRIM(IFERROR(VLOOKUP(A10,'Cadastro Geral Campistas'!$A:$R,10,0),"")))<>"não",LOWER(TRIM(IFERROR(VLOOKUP(A10,'Cadastro Geral Campistas'!$A:$R,10,0),"")))<>"nao",LOWER(TRIM(IFERROR(VLOOKUP(A10,'Cadastro Geral Campistas'!$A:$R,10,0),"")))<>"0"),IFERROR(VLOOKUP(A10,'Cadastro Geral Campistas'!$A:$R,10,0),"")&IF(AND(IFERROR(VLOOKUP(A10,'Cadastro Geral Campistas'!$A:$R,15,0),"")<>"",LOWER(TRIM(IFERROR(VLOOKUP(A10,'Cadastro Geral Campistas'!$A:$R,15,0),"")))<>"não",LOWER(TRIM(IFERROR(VLOOKUP(A10,'Cadastro Geral Campistas'!$A:$R,15,0),"")))<>"nao",LOWER(TRIM(IFERROR(VLOOKUP(A10,'Cadastro Geral Campistas'!$A:$R,15,0),"")))<>"0")," | Alergia: "&IFERROR(VLOOKUP(A10,'Cadastro Geral Campistas'!$A:$R,15,0),""),""),IF(AND(IFERROR(VLOOKUP(A10,'Cadastro Geral Campistas'!$A:$R,15,0),"")<>"",LOWER(TRIM(IFERROR(VLOOKUP(A10,'Cadastro Geral Campistas'!$A:$R,15,0),"")))<>"não",LOWER(TRIM(IFERROR(VLOOKUP(A10,'Cadastro Geral Campistas'!$A:$R,15,0),"")))<>"nao",LOWER(TRIM(IFERROR(VLOOKUP(A10,'Cadastro Geral Campistas'!$A:$R,15,0),"")))<>"0"),"Alergia: "&IFERROR(VLOOKUP(A10,'Cadastro Geral Campistas'!$A:$R,15,0),""),"")))) | J10: =IFERROR(VLOOKUP(A10,'Cadastro Geral Campistas'!$A:$R,4,0),"")
A11: 50 | B11: =IFERROR(VLOOKUP(A11,'Cadastro Geral Campistas'!$A:$R,2,0),"") | C11: =IFERROR(VLOOKUP(A11,'Cadastro Geral Campistas'!$A:$R,5,0),"") | D11: =IFERROR(VLOOKUP(A11,'Cadastro Geral Campistas'!$A:$R,6,0),"") | E11: =IFERROR(VLOOKUP(A11,'Cadastro Geral Campistas'!$A:$R,7,0),"") | F11: =IFERROR(VLOOKUP(A11,'Cadastro Geral Campistas'!$A:$R,9,0),"") | G11: =IFERROR(VLOOKUP(A11,'Cadastro Geral Campistas'!$A:$R,3,0),"") | H11: =IFERROR(VLOOKUP(A11,'Cadastro Geral Campistas'!$A:$R,8,0),"") | I11: =IF(AND(IFERROR(VLOOKUP(A11,'Cadastro Geral Campistas'!$A:$R,18,0),0)>0,COUNTIF($A$9:$A$24,IFERROR(VLOOKUP(A11,'Cadastro Geral Campistas'!$A:$R,18,0),0))>0),"⚠️ CONFLITO! Cônjuge na mesma tribo: "&IFERROR(VLOOKUP(IFERROR(VLOOKUP(A11,'Cadastro Geral Campistas'!$A:$R,18,0),0),'Cadastro Geral Campistas'!$A:$R,2,""),""),TRIM(IF(AND(IFERROR(VLOOKUP(A11,'Cadastro Geral Campistas'!$A:$R,10,0),"")<>"",LOWER(TRIM(IFERROR(VLOOKUP(A11,'Cadastro Geral Campistas'!$A:$R,10,0),"")))<>"não",LOWER(TRIM(IFERROR(VLOOKUP(A11,'Cadastro Geral Campistas'!$A:$R,10,0),"")))<>"nao",LOWER(TRIM(IFERROR(VLOOKUP(A11,'Cadastro Geral Campistas'!$A:$R,10,0),"")))<>"0"),IFERROR(VLOOKUP(A11,'Cadastro Geral Campistas'!$A:$R,10,0),"")&IF(AND(IFERROR(VLOOKUP(A11,'Cadastro Geral Campistas'!$A:$R,15,0),"")<>"",LOWER(TRIM(IFERROR(VLOOKUP(A11,'Cadastro Geral Campistas'!$A:$R,15,0),"")))<>"não",LOWER(TRIM(IFERROR(VLOOKUP(A11,'Cadastro Geral Campistas'!$A:$R,15,0),"")))<>"nao",LOWER(TRIM(IFERROR(VLOOKUP(A11,'Cadastro Geral Campistas'!$A:$R,15,0),"")))<>"0")," | Alergia: "&IFERROR(VLOOKUP(A11,'Cadastro Geral Campistas'!$A:$R,15,0),""),""),IF(AND(IFERROR(VLOOKUP(A11,'Cadastro Geral Campistas'!$A:$R,15,0),"")<>"",LOWER(TRIM(IFERROR(VLOOKUP(A11,'Cadastro Geral Campistas'!$A:$R,15,0),"")))<>"não",LOWER(TRIM(IFERROR(VLOOKUP(A11,'Cadastro Geral Campistas'!$A:$R,15,0),"")))<>"nao",LOWER(TRIM(IFERROR(VLOOKUP(A11,'Cadastro Geral Campistas'!$A:$R,15,0),"")))<>"0"),"Alergia: "&IFERROR(VLOOKUP(A11,'Cadastro Geral Campistas'!$A:$R,15,0),""),"")))) | J11: =IFERROR(VLOOKUP(A11,'Cadastro Geral Campistas'!$A:$R,4,0),"")
A12: 79 | B12: =IFERROR(VLOOKUP(A12,'Cadastro Geral Campistas'!$A:$R,2,0),"") | C12: =IFERROR(VLOOKUP(A12,'Cadastro Geral Campistas'!$A:$R,5,0),"") | D12: =IFERROR(VLOOKUP(A12,'Cadastro Geral Campistas'!$A:$R,6,0),"") | E12: =IFERROR(VLOOKUP(A12,'Cadastro Geral Campistas'!$A:$R,7,0),"") | F12: =IFERROR(VLOOKUP(A12,'Cadastro Geral Campistas'!$A:$R,9,0),"") | G12: =IFERROR(VLOOKUP(A12,'Cadastro Geral Campistas'!$A:$R,3,0),"") | H12: =IFERROR(VLOOKUP(A12,'Cadastro Geral Campistas'!$A:$R,8,0),"") | I12: =IF(AND(IFERROR(VLOOKUP(A12,'Cadastro Geral Campistas'!$A:$R,18,0),0)>0,COUNTIF($A$9:$A$24,IFERROR(VLOOKUP(A12,'Cadastro Geral Campistas'!$A:$R,18,0),0))>0),"⚠️ CONFLITO! Cônjuge na mesma tribo: "&IFERROR(VLOOKUP(IFERROR(VLOOKUP(A12,'Cadastro Geral Campistas'!$A:$R,18,0),0),'Cadastro Geral Campistas'!$A:$R,2,""),""),TRIM(IF(AND(IFERROR(VLOOKUP(A12,'Cadastro Geral Campistas'!$A:$R,10,0),"")<>"",LOWER(TRIM(IFERROR(VLOOKUP(A12,'Cadastro Geral Campistas'!$A:$R,10,0),"")))<>"não",LOWER(TRIM(IFERROR(VLOOKUP(A12,'Cadastro Geral Campistas'!$A:$R,10,0),"")))<>"nao",LOWER(TRIM(IFERROR(VLOOKUP(A12,'Cadastro Geral Campistas'!$A:$R,10,0),"")))<>"0"),IFERROR(VLOOKUP(A12,'Cadastro Geral Campistas'!$A:$R,10,0),"")&IF(AND(IFERROR(VLOOKUP(A12,'Cadastro Geral Campistas'!$A:$R,15,0),"")<>"",LOWER(TRIM(IFERROR(VLOOKUP(A12,'Cadastro Geral Campistas'!$A:$R,15,0),"")))<>"não",LOWER(TRIM(IFERROR(VLOOKUP(A12,'Cadastro Geral Campistas'!$A:$R,15,0),"")))<>"nao",LOWER(TRIM(IFERROR(VLOOKUP(A12,'Cadastro Geral Campistas'!$A:$R,15,0),"")))<>"0")," | Alergia: "&IFERROR(VLOOKUP(A12,'Cadastro Geral Campistas'!$A:$R,15,0),""),""),IF(AND(IFERROR(VLOOKUP(A12,'Cadastro Geral Campistas'!$A:$R,15,0),"")<>"",LOWER(TRIM(IFERROR(VLOOKUP(A12,'Cadastro Geral Campistas'!$A:$R,15,0),"")))<>"não",LOWER(TRIM(IFERROR(VLOOKUP(A12,'Cadastro Geral Campistas'!$A:$R,15,0),"")))<>"nao",LOWER(TRIM(IFERROR(VLOOKUP(A12,'Cadastro Geral Campistas'!$A:$R,15,0),"")))<>"0"),"Alergia: "&IFERROR(VLOOKUP(A12,'Cadastro Geral Campistas'!$A:$R,15,0),""),"")))) | J12: =IFERROR(VLOOKUP(A12,'Cadastro Geral Campistas'!$A:$R,4,0),"")
A13: 101 | B13: =IFERROR(VLOOKUP(A13,'Cadastro Geral Campistas'!$A:$R,2,0),"") | C13: =IFERROR(VLOOKUP(A13,'Cadastro Geral Campistas'!$A:$R,5,0),"") | D13: =IFERROR(VLOOKUP(A13,'Cadastro Geral Campistas'!$A:$R,6,0),"") | E13: =IFERROR(VLOOKUP(A13,'Cadastro Geral Campistas'!$A:$R,7,0),"") | F13: =IFERROR(VLOOKUP(A13,'Cadastro Geral Campistas'!$A:$R,9,0),"") | G13: =IFERROR(VLOOKUP(A13,'Cadastro Geral Campistas'!$A:$R,3,0),"") | H13: =IFERROR(VLOOKUP(A13,'Cadastro Geral Campistas'!$A:$R,8,0),"") | I13: =IF(AND(IFERROR(VLOOKUP(A13,'Cadastro Geral Campistas'!$A:$R,18,0),0)>0,COUNTIF($A$9:$A$24,IFERROR(VLOOKUP(A13,'Cadastro Geral Campistas'!$A:$R,18,0),0))>0),"⚠️ CONFLITO! Cônjuge na mesma tribo: "&IFERROR(VLOOKUP(IFERROR(VLOOKUP(A13,'Cadastro Geral Campistas'!$A:$R,18,0),0),'Cadastro Geral Campistas'!$A:$R,2,""),""),TRIM(IF(AND(IFERROR(VLOOKUP(A13,'Cadastro Geral Campistas'!$A:$R,10,0),"")<>"",LOWER(TRIM(IFERROR(VLOOKUP(A13,'Cadastro Geral Campistas'!$A:$R,10,0),"")))<>"não",LOWER(TRIM(IFERROR(VLOOKUP(A13,'Cadastro Geral Campistas'!$A:$R,10,0),"")))<>"nao",LOWER(TRIM(IFERROR(VLOOKUP(A13,'Cadastro Geral Campistas'!$A:$R,10,0),"")))<>"0"),IFERROR(VLOOKUP(A13,'Cadastro Geral Campistas'!$A:$R,10,0),"")&IF(AND(IFERROR(VLOOKUP(A13,'Cadastro Geral Campistas'!$A:$R,15,0),"")<>"",LOWER(TRIM(IFERROR(VLOOKUP(A13,'Cadastro Geral Campistas'!$A:$R,15,0),"")))<>"não",LOWER(TRIM(IFERROR(VLOOKUP(A13,'Cadastro Geral Campistas'!$A:$R,15,0),"")))<>"nao",LOWER(TRIM(IFERROR(VLOOKUP(A13,'Cadastro Geral Campistas'!$A:$R,15,0),"")))<>"0")," | Alergia: "&IFERROR(VLOOKUP(A13,'Cadastro Geral Campistas'!$A:$R,15,0),""),""),IF(AND(IFERROR(VLOOKUP(A13,'Cadastro Geral Campistas'!$A:$R,15,0),"")<>"",LOWER(TRIM(IFERROR(VLOOKUP(A13,'Cadastro Geral Campistas'!$A:$R,15,0),"")))<>"não",LOWER(TRIM(IFERROR(VLOOKUP(A13,'Cadastro Geral Campistas'!$A:$R,15,0),"")))<>"nao",LOWER(TRIM(IFERROR(VLOOKUP(A13,'Cadastro Geral Campistas'!$A:$R,15,0),"")))<>"0"),"Alergia: "&IFERROR(VLOOKUP(A13,'Cadastro Geral Campistas'!$A:$R,15,0),""),"")))) | J13: =IFERROR(VLOOKUP(A13,'Cadastro Geral Campistas'!$A:$R,4,0),"")
A14: 102 | B14: =IFERROR(VLOOKUP(A14,'Cadastro Geral Campistas'!$A:$R,2,0),"") | C14: =IFERROR(VLOOKUP(A14,'Cadastro Geral Campistas'!$A:$R,5,0),"") | D14: =IFERROR(VLOOKUP(A14,'Cadastro Geral Campistas'!$A:$R,6,0),"") | E14: =IFERROR(VLOOKUP(A14,'Cadastro Geral Campistas'!$A:$R,7,0),"") | F14: =IFERROR(VLOOKUP(A14,'Cadastro Geral Campistas'!$A:$R,9,0),"") | G14: =IFERROR(VLOOKUP(A14,'Cadastro Geral Campistas'!$A:$R,3,0),"") | H14: =IFERROR(VLOOKUP(A14,'Cadastro Geral Campistas'!$A:$R,8,0),"") | I14: =IF(AND(IFERROR(VLOOKUP(A14,'Cadastro Geral Campistas'!$A:$R,18,0),0)>0,COUNTIF($A$9:$A$24,IFERROR(VLOOKUP(A14,'Cadastro Geral Campistas'!$A:$R,18,0),0))>0),"⚠️ CONFLITO! Cônjuge na mesma tribo: "&IFERROR(VLOOKUP(IFERROR(VLOOKUP(A14,'Cadastro Geral Campistas'!$A:$R,18,0),0),'Cadastro Geral Campistas'!$A:$R,2,""),""),TRIM(IF(AND(IFERROR(VLOOKUP(A14,'Cadastro Geral Campistas'!$A:$R,10,0),"")<>"",LOWER(TRIM(IFERROR(VLOOKUP(A14,'Cadastro Geral Campistas'!$A:$R,10,0),"")))<>"não",LOWER(TRIM(IFERROR(VLOOKUP(A14,'Cadastro Geral Campistas'!$A:$R,10,0),"")))<>"nao",LOWER(TRIM(IFERROR(VLOOKUP(A14,'Cadastro Geral Campistas'!$A:$R,10,0),"")))<>"0"),IFERROR(VLOOKUP(A14,'Cadastro Geral Campistas'!$A:$R,10,0),"")&IF(AND(IFERROR(VLOOKUP(A14,'Cadastro Geral Campistas'!$A:$R,15,0),"")<>"",LOWER(TRIM(IFERROR(VLOOKUP(A14,'Cadastro Geral Campistas'!$A:$R,15,0),"")))<>"não",LOWER(TRIM(IFERROR(VLOOKUP(A14,'Cadastro Geral Campistas'!$A:$R,15,0),"")))<>"nao",LOWER(TRIM(IFERROR(VLOOKUP(A14,'Cadastro Geral Campistas'!$A:$R,15,0),"")))<>"0")," | Alergia: "&IFERROR(VLOOKUP(A14,'Cadastro Geral Campistas'!$A:$R,15,0),""),""),IF(AND(IFERROR(VLOOKUP(A14,'Cadastro Geral Campistas'!$A:$R,15,0),"")<>"",LOWER(TRIM(IFERROR(VLOOKUP(A14,'Cadastro Geral Campistas'!$A:$R,15,0),"")))<>"não",LOWER(TRIM(IFERROR(VLOOKUP(A14,'Cadastro Geral Campistas'!$A:$R,15,0),"")))<>"nao",LOWER(TRIM(IFERROR(VLOOKUP(A14,'Cadastro Geral Campistas'!$A:$R,15,0),"")))<>"0"),"Alergia: "&IFERROR(VLOOKUP(A14,'Cadastro Geral Campistas'!$A:$R,15,0),""),"")))) | J14: =IFERROR(VLOOKUP(A14,'Cadastro Geral Campistas'!$A:$R,4,0),"")
A15: 106 | B15: =IFERROR(VLOOKUP(A15,'Cadastro Geral Campistas'!$A:$R,2,0),"") | C15: =IFERROR(VLOOKUP(A15,'Cadastro Geral Campistas'!$A:$R,5,0),"") | D15: =IFERROR(VLOOKUP(A15,'Cadastro Geral Campistas'!$A:$R,6,0),"") | E15: =IFERROR(VLOOKUP(A15,'Cadastro Geral Campistas'!$A:$R,7,0),"") | F15: =IFERROR(VLOOKUP(A15,'Cadastro Geral Campistas'!$A:$R,9,0),"") | G15: =IFERROR(VLOOKUP(A15,'Cadastro Geral Campistas'!$A:$R,3,0),"") | H15: =IFERROR(VLOOKUP(A15,'Cadastro Geral Campistas'!$A:$R,8,0),"") | I15: =IF(AND(IFERROR(VLOOKUP(A15,'Cadastro Geral Campistas'!$A:$R,18,0),0)>0,COUNTIF($A$9:$A$24,IFERROR(VLOOKUP(A15,'Cadastro Geral Campistas'!$A:$R,18,0),0))>0),"⚠️ CONFLITO! Cônjuge na mesma tribo: "&IFERROR(VLOOKUP(IFERROR(VLOOKUP(A15,'Cadastro Geral Campistas'!$A:$R,18,0),0),'Cadastro Geral Campistas'!$A:$R,2,""),""),TRIM(IF(AND(IFERROR(VLOOKUP(A15,'Cadastro Geral Campistas'!$A:$R,10,0),"")<>"",LOWER(TRIM(IFERROR(VLOOKUP(A15,'Cadastro Geral Campistas'!$A:$R,10,0),"")))<>"não",LOWER(TRIM(IFERROR(VLOOKUP(A15,'Cadastro Geral Campistas'!$A:$R,10,0),"")))<>"nao",LOWER(TRIM(IFERROR(VLOOKUP(A15,'Cadastro Geral Campistas'!$A:$R,10,0),"")))<>"0"),IFERROR(VLOOKUP(A15,'Cadastro Geral Campistas'!$A:$R,10,0),"")&IF(AND(IFERROR(VLOOKUP(A15,'Cadastro Geral Campistas'!$A:$R,15,0),"")<>"",LOWER(TRIM(IFERROR(VLOOKUP(A15,'Cadastro Geral Campistas'!$A:$R,15,0),"")))<>"não",LOWER(TRIM(IFERROR(VLOOKUP(A15,'Cadastro Geral Campistas'!$A:$R,15,0),"")))<>"nao",LOWER(TRIM(IFERROR(VLOOKUP(A15,'Cadastro Geral Campistas'!$A:$R,15,0),"")))<>"0")," | Alergia: "&IFERROR(VLOOKUP(A15,'Cadastro Geral Campistas'!$A:$R,15,0),""),""),IF(AND(IFERROR(VLOOKUP(A15,'Cadastro Geral Campistas'!$A:$R,15,0),"")<>"",LOWER(TRIM(IFERROR(VLOOKUP(A15,'Cadastro Geral Campistas'!$A:$R,15,0),"")))<>"não",LOWER(TRIM(IFERROR(VLOOKUP(A15,'Cadastro Geral Campistas'!$A:$R,15,0),"")))<>"nao",LOWER(TRIM(IFERROR(VLOOKUP(A15,'Cadastro Geral Campistas'!$A:$R,15,0),"")))<>"0"),"Alergia: "&IFERROR(VLOOKUP(A15,'Cadastro Geral Campistas'!$A:$R,15,0),""),"")))) | J15: =IFERROR(VLOOKUP(A15,'Cadastro Geral Campistas'!$A:$R,4,0),"")
A16: 129 | B16: =IFERROR(VLOOKUP(A16,'Cadastro Geral Campistas'!$A:$R,2,0),"") | C16: =IFERROR(VLOOKUP(A16,'Cadastro Geral Campistas'!$A:$R,5,0),"") | D16: =IFERROR(VLOOKUP(A16,'Cadastro Geral Campistas'!$A:$R,6,0),"") | E16: =IFERROR(VLOOKUP(A16,'Cadastro Geral Campistas'!$A:$R,7,0),"") | F16: =IFERROR(VLOOKUP(A16,'Cadastro Geral Campistas'!$A:$R,9,0),"") | G16: =IFERROR(VLOOKUP(A16,'Cadastro Geral Campistas'!$A:$R,3,0),"") | H16: =IFERROR(VLOOKUP(A16,'Cadastro Geral Campistas'!$A:$R,8,0),"") | I16: =IF(AND(IFERROR(VLOOKUP(A16,'Cadastro Geral Campistas'!$A:$R,18,0),0)>0,COUNTIF($A$9:$A$24,IFERROR(VLOOKUP(A16,'Cadastro Geral Campistas'!$A:$R,18,0),0))>0),"⚠️ CONFLITO! Cônjuge na mesma tribo: "&IFERROR(VLOOKUP(IFERROR(VLOOKUP(A16,'Cadastro Geral Campistas'!$A:$R,18,0),0),'Cadastro Geral Campistas'!$A:$R,2,""),""),TRIM(IF(AND(IFERROR(VLOOKUP(A16,'Cadastro Geral Campistas'!$A:$R,10,0),"")<>"",LOWER(TRIM(IFERROR(VLOOKUP(A16,'Cadastro Geral Campistas'!$A:$R,10,0),"")))<>"não",LOWER(TRIM(IFERROR(VLOOKUP(A16,'Cadastro Geral Campistas'!$A:$R,10,0),"")))<>"nao",LOWER(TRIM(IFERROR(VLOOKUP(A16,'Cadastro Geral Campistas'!$A:$R,10,0),"")))<>"0"),IFERROR(VLOOKUP(A16,'Cadastro Geral Campistas'!$A:$R,10,0),"")&IF(AND(IFERROR(VLOOKUP(A16,'Cadastro Geral Campistas'!$A:$R,15,0),"")<>"",LOWER(TRIM(IFERROR(VLOOKUP(A16,'Cadastro Geral Campistas'!$A:$R,15,0),"")))<>"não",LOWER(TRIM(IFERROR(VLOOKUP(A16,'Cadastro Geral Campistas'!$A:$R,15,0),"")))<>"nao",LOWER(TRIM(IFERROR(VLOOKUP(A16,'Cadastro Geral Campistas'!$A:$R,15,0),"")))<>"0")," | Alergia: "&IFERROR(VLOOKUP(A16,'Cadastro Geral Campistas'!$A:$R,15,0),""),""),IF(AND(IFERROR(VLOOKUP(A16,'Cadastro Geral Campistas'!$A:$R,15,0),"")<>"",LOWER(TRIM(IFERROR(VLOOKUP(A16,'Cadastro Geral Campistas'!$A:$R,15,0),"")))<>"não",LOWER(TRIM(IFERROR(VLOOKUP(A16,'Cadastro Geral Campistas'!$A:$R,15,0),"")))<>"nao",LOWER(TRIM(IFERROR(VLOOKUP(A16,'Cadastro Geral Campistas'!$A:$R,15,0),"")))<>"0"),"Alergia: "&IFERROR(VLOOKUP(A16,'Cadastro Geral Campistas'!$A:$R,15,0),""),"")))) | J16: =IFERROR(VLOOKUP(A16,'Cadastro Geral Campistas'!$A:$R,4,0),"")
A17: 19 | B17: =IFERROR(VLOOKUP(A17,'Cadastro Geral Campistas'!$A:$R,2,0),"") | C17: =IFERROR(VLOOKUP(A17,'Cadastro Geral Campistas'!$A:$R,5,0),"") | D17: =IFERROR(VLOOKUP(A17,'Cadastro Geral Campistas'!$A:$R,6,0),"") | E17: =IFERROR(VLOOKUP(A17,'Cadastro Geral Campistas'!$A:$R,7,0),"") | F17: =IFERROR(VLOOKUP(A17,'Cadastro Geral Campistas'!$A:$R,9,0),"") | G17: =IFERROR(VLOOKUP(A17,'Cadastro Geral Campistas'!$A:$R,3,0),"") | H17: =IFERROR(VLOOKUP(A17,'Cadastro Geral Campistas'!$A:$R,8,0),"") | I17: =IF(AND(IFERROR(VLOOKUP(A17,'Cadastro Geral Campistas'!$A:$R,18,0),0)>0,COUNTIF($A$9:$A$24,IFERROR(VLOOKUP(A17,'Cadastro Geral Campistas'!$A:$R,18,0),0))>0),"⚠️ CONFLITO! Cônjuge na mesma tribo: "&IFERROR(VLOOKUP(IFERROR(VLOOKUP(A17,'Cadastro Geral Campistas'!$A:$R,18,0),0),'Cadastro Geral Campistas'!$A:$R,2,""),""),TRIM(IF(AND(IFERROR(VLOOKUP(A17,'Cadastro Geral Campistas'!$A:$R,10,0),"")<>"",LOWER(TRIM(IFERROR(VLOOKUP(A17,'Cadastro Geral Campistas'!$A:$R,10,0),"")))<>"não",LOWER(TRIM(IFERROR(VLOOKUP(A17,'Cadastro Geral Campistas'!$A:$R,10,0),"")))<>"nao",LOWER(TRIM(IFERROR(VLOOKUP(A17,'Cadastro Geral Campistas'!$A:$R,10,0),"")))<>"0"),IFERROR(VLOOKUP(A17,'Cadastro Geral Campistas'!$A:$R,10,0),"")&IF(AND(IFERROR(VLOOKUP(A17,'Cadastro Geral Campistas'!$A:$R,15,0),"")<>"",LOWER(TRIM(IFERROR(VLOOKUP(A17,'Cadastro Geral Campistas'!$A:$R,15,0),"")))<>"não",LOWER(TRIM(IFERROR(VLOOKUP(A17,'Cadastro Geral Campistas'!$A:$R,15,0),"")))<>"nao",LOWER(TRIM(IFERROR(VLOOKUP(A17,'Cadastro Geral Campistas'!$A:$R,15,0),"")))<>"0")," | Alergia: "&IFERROR(VLOOKUP(A17,'Cadastro Geral Campistas'!$A:$R,15,0),""),""),IF(AND(IFERROR(VLOOKUP(A17,'Cadastro Geral Campistas'!$A:$R,15,0),"")<>"",LOWER(TRIM(IFERROR(VLOOKUP(A17,'Cadastro Geral Campistas'!$A:$R,15,0),"")))<>"não",LOWER(TRIM(IFERROR(VLOOKUP(A17,'Cadastro Geral Campistas'!$A:$R,15,0),"")))<>"nao",LOWER(TRIM(IFERROR(VLOOKUP(A17,'Cadastro Geral Campistas'!$A:$R,15,0),"")))<>"0"),"Alergia: "&IFERROR(VLOOKUP(A17,'Cadastro Geral Campistas'!$A:$R,15,0),""),"")))) | J17: =IFERROR(VLOOKUP(A17,'Cadastro Geral Campistas'!$A:$R,4,0),"")
A18: 27 | B18: =IFERROR(VLOOKUP(A18,'Cadastro Geral Campistas'!$A:$R,2,0),"") | C18: =IFERROR(VLOOKUP(A18,'Cadastro Geral Campistas'!$A:$R,5,0),"") | D18: =IFERROR(VLOOKUP(A18,'Cadastro Geral Campistas'!$A:$R,6,0),"") | E18: =IFERROR(VLOOKUP(A18,'Cadastro Geral Campistas'!$A:$R,7,0),"") | F18: =IFERROR(VLOOKUP(A18,'Cadastro Geral Campistas'!$A:$R,9,0),"") | G18: =IFERROR(VLOOKUP(A18,'Cadastro Geral Campistas'!$A:$R,3,0),"") | H18: =IFERROR(VLOOKUP(A18,'Cadastro Geral Campistas'!$A:$R,8,0),"") | I18: =IF(AND(IFERROR(VLOOKUP(A18,'Cadastro Geral Campistas'!$A:$R,18,0),0)>0,COUNTIF($A$9:$A$24,IFERROR(VLOOKUP(A18,'Cadastro Geral Campistas'!$A:$R,18,0),0))>0),"⚠️ CONFLITO! Cônjuge na mesma tribo: "&IFERROR(VLOOKUP(IFERROR(VLOOKUP(A18,'Cadastro Geral Campistas'!$A:$R,18,0),0),'Cadastro Geral Campistas'!$A:$R,2,""),""),TRIM(IF(AND(IFERROR(VLOOKUP(A18,'Cadastro Geral Campistas'!$A:$R,10,0),"")<>"",LOWER(TRIM(IFERROR(VLOOKUP(A18,'Cadastro Geral Campistas'!$A:$R,10,0),"")))<>"não",LOWER(TRIM(IFERROR(VLOOKUP(A18,'Cadastro Geral Campistas'!$A:$R,10,0),"")))<>"nao",LOWER(TRIM(IFERROR(VLOOKUP(A18,'Cadastro Geral Campistas'!$A:$R,10,0),"")))<>"0"),IFERROR(VLOOKUP(A18,'Cadastro Geral Campistas'!$A:$R,10,0),"")&IF(AND(IFERROR(VLOOKUP(A18,'Cadastro Geral Campistas'!$A:$R,15,0),"")<>"",LOWER(TRIM(IFERROR(VLOOKUP(A18,'Cadastro Geral Campistas'!$A:$R,15,0),"")))<>"não",LOWER(TRIM(IFERROR(VLOOKUP(A18,'Cadastro Geral Campistas'!$A:$R,15,0),"")))<>"nao",LOWER(TRIM(IFERROR(VLOOKUP(A18,'Cadastro Geral Campistas'!$A:$R,15,0),"")))<>"0")," | Alergia: "&IFERROR(VLOOKUP(A18,'Cadastro Geral Campistas'!$A:$R,15,0),""),""),IF(AND(IFERROR(VLOOKUP(A18,'Cadastro Geral Campistas'!$A:$R,15,0),"")<>"",LOWER(TRIM(IFERROR(VLOOKUP(A18,'Cadastro Geral Campistas'!$A:$R,15,0),"")))<>"não",LOWER(TRIM(IFERROR(VLOOKUP(A18,'Cadastro Geral Campistas'!$A:$R,15,0),"")))<>"nao",LOWER(TRIM(IFERROR(VLOOKUP(A18,'Cadastro Geral Campistas'!$A:$R,15,0),"")))<>"0"),"Alergia: "&IFERROR(VLOOKUP(A18,'Cadastro Geral Campistas'!$A:$R,15,0),""),"")))) | J18: =IFERROR(VLOOKUP(A18,'Cadastro Geral Campistas'!$A:$R,4,0),"")
A19: 63 | B19: =IFERROR(VLOOKUP(A19,'Cadastro Geral Campistas'!$A:$R,2,0),"") | C19: =IFERROR(VLOOKUP(A19,'Cadastro Geral Campistas'!$A:$R,5,0),"") | D19: =IFERROR(VLOOKUP(A19,'Cadastro Geral Campistas'!$A:$R,6,0),"") | E19: =IFERROR(VLOOKUP(A19,'Cadastro Geral Campistas'!$A:$R,7,0),"") | F19: =IFERROR(VLOOKUP(A19,'Cadastro Geral Campistas'!$A:$R,9,0),"") | G19: =IFERROR(VLOOKUP(A19,'Cadastro Geral Campistas'!$A:$R,3,0),"") | H19: =IFERROR(VLOOKUP(A19,'Cadastro Geral Campistas'!$A:$R,8,0),"") | I19: =IF(AND(IFERROR(VLOOKUP(A19,'Cadastro Geral Campistas'!$A:$R,18,0),0)>0,COUNTIF($A$9:$A$24,IFERROR(VLOOKUP(A19,'Cadastro Geral Campistas'!$A:$R,18,0),0))>0),"⚠️ CONFLITO! Cônjuge na mesma tribo: "&IFERROR(VLOOKUP(IFERROR(VLOOKUP(A19,'Cadastro Geral Campistas'!$A:$R,18,0),0),'Cadastro Geral Campistas'!$A:$R,2,""),""),TRIM(IF(AND(IFERROR(VLOOKUP(A19,'Cadastro Geral Campistas'!$A:$R,10,0),"")<>"",LOWER(TRIM(IFERROR(VLOOKUP(A19,'Cadastro Geral Campistas'!$A:$R,10,0),"")))<>"não",LOWER(TRIM(IFERROR(VLOOKUP(A19,'Cadastro Geral Campistas'!$A:$R,10,0),"")))<>"nao",LOWER(TRIM(IFERROR(VLOOKUP(A19,'Cadastro Geral Campistas'!$A:$R,10,0),"")))<>"0"),IFERROR(VLOOKUP(A19,'Cadastro Geral Campistas'!$A:$R,10,0),"")&IF(AND(IFERROR(VLOOKUP(A19,'Cadastro Geral Campistas'!$A:$R,15,0),"")<>"",LOWER(TRIM(IFERROR(VLOOKUP(A19,'Cadastro Geral Campistas'!$A:$R,15,0),"")))<>"não",LOWER(TRIM(IFERROR(VLOOKUP(A19,'Cadastro Geral Campistas'!$A:$R,15,0),"")))<>"nao",LOWER(TRIM(IFERROR(VLOOKUP(A19,'Cadastro Geral Campistas'!$A:$R,15,0),"")))<>"0")," | Alergia: "&IFERROR(VLOOKUP(A19,'Cadastro Geral Campistas'!$A:$R,15,0),""),""),IF(AND(IFERROR(VLOOKUP(A19,'Cadastro Geral Campistas'!$A:$R,15,0),"")<>"",LOWER(TRIM(IFERROR(VLOOKUP(A19,'Cadastro Geral Campistas'!$A:$R,15,0),"")))<>"não",LOWER(TRIM(IFERROR(VLOOKUP(A19,'Cadastro Geral Campistas'!$A:$R,15,0),"")))<>"nao",LOWER(TRIM(IFERROR(VLOOKUP(A19,'Cadastro Geral Campistas'!$A:$R,15,0),"")))<>"0"),"Alergia: "&IFERROR(VLOOKUP(A19,'Cadastro Geral Campistas'!$A:$R,15,0),""),"")))) | J19: =IFERROR(VLOOKUP(A19,'Cadastro Geral Campistas'!$A:$R,4,0),"")
A20: 78 | B20: =IFERROR(VLOOKUP(A20,'Cadastro Geral Campistas'!$A:$R,2,0),"") | C20: =IFERROR(VLOOKUP(A20,'Cadastro Geral Campistas'!$A:$R,5,0),"") | D20: =IFERROR(VLOOKUP(A20,'Cadastro Geral Campistas'!$A:$R,6,0),"") | E20: =IFERROR(VLOOKUP(A20,'Cadastro Geral Campistas'!$A:$R,7,0),"") | F20: =IFERROR(VLOOKUP(A20,'Cadastro Geral Campistas'!$A:$R,9,0),"") | G20: =IFERROR(VLOOKUP(A20,'Cadastro Geral Campistas'!$A:$R,3,0),"") | H20: =IFERROR(VLOOKUP(A20,'Cadastro Geral Campistas'!$A:$R,8,0),"") | I20: =IF(AND(IFERROR(VLOOKUP(A20,'Cadastro Geral Campistas'!$A:$R,18,0),0)>0,COUNTIF($A$9:$A$24,IFERROR(VLOOKUP(A20,'Cadastro Geral Campistas'!$A:$R,18,0),0))>0),"⚠️ CONFLITO! Cônjuge na mesma tribo: "&IFERROR(VLOOKUP(IFERROR(VLOOKUP(A20,'Cadastro Geral Campistas'!$A:$R,18,0),0),'Cadastro Geral Campistas'!$A:$R,2,""),""),TRIM(IF(AND(IFERROR(VLOOKUP(A20,'Cadastro Geral Campistas'!$A:$R,10,0),"")<>"",LOWER(TRIM(IFERROR(VLOOKUP(A20,'Cadastro Geral Campistas'!$A:$R,10,0),"")))<>"não",LOWER(TRIM(IFERROR(VLOOKUP(A20,'Cadastro Geral Campistas'!$A:$R,10,0),"")))<>"nao",LOWER(TRIM(IFERROR(VLOOKUP(A20,'Cadastro Geral Campistas'!$A:$R,10,0),"")))<>"0"),IFERROR(VLOOKUP(A20,'Cadastro Geral Campistas'!$A:$R,10,0),"")&IF(AND(IFERROR(VLOOKUP(A20,'Cadastro Geral Campistas'!$A:$R,15,0),"")<>"",LOWER(TRIM(IFERROR(VLOOKUP(A20,'Cadastro Geral Campistas'!$A:$R,15,0),"")))<>"não",LOWER(TRIM(IFERROR(VLOOKUP(A20,'Cadastro Geral Campistas'!$A:$R,15,0),"")))<>"nao",LOWER(TRIM(IFERROR(VLOOKUP(A20,'Cadastro Geral Campistas'!$A:$R,15,0),"")))<>"0")," | Alergia: "&IFERROR(VLOOKUP(A20,'Cadastro Geral Campistas'!$A:$R,15,0),""),""),IF(AND(IFERROR(VLOOKUP(A20,'Cadastro Geral Campistas'!$A:$R,15,0),"")<>"",LOWER(TRIM(IFERROR(VLOOKUP(A20,'Cadastro Geral Campistas'!$A:$R,15,0),"")))<>"não",LOWER(TRIM(IFERROR(VLOOKUP(A20,'Cadastro Geral Campistas'!$A:$R,15,0),"")))<>"nao",LOWER(TRIM(IFERROR(VLOOKUP(A20,'Cadastro Geral Campistas'!$A:$R,15,0),"")))<>"0"),"Alergia: "&IFERROR(VLOOKUP(A20,'Cadastro Geral Campistas'!$A:$R,15,0),""),"")))) | J20: =IFERROR(VLOOKUP(A20,'Cadastro Geral Campistas'!$A:$R,4,0),"")
... A24: 140 | B24: =IFERROR(VLOOKUP(A24,'Cadastro Geral Campistas'!$A:$R,2,0),"") | C24: =IFERROR(VLOOKUP(A24,'Cadastro Geral Campistas'!$A:$R,5,0),"") | D24: =IFERROR(VLOOKUP(A24,'Cadastro Geral Campistas'!$A:$R,6,0),"") | E24: =IFERROR(VLOOKUP(A24,'Cadastro Geral Campistas'!$A:$R,7,0),"") | F24: =IFERROR(VLOOKUP(A24,'Cadastro Geral Campistas'!$A:$R,9,0),"") | G24: =IFERROR(VLOOKUP(A24,'Cadastro Geral Campistas'!$A:$R,3,0),"") | H24: =IFERROR(VLOOKUP(A24,'Cadastro Geral Campistas'!$A:$R,8,0),"") | I24: =IF(AND(IFERROR(VLOOKUP(A24,'Cadastro Geral Campistas'!$A:$R,18,0),0)>0,COUNTIF($A$9:$A$24,IFERROR(VLOOKUP(A24,'Cadastro Geral Campistas'!$A:$R,18,0),0))>0),"⚠️ CONFLITO! Cônjuge na mesma tribo: "&IFERROR(VLOOKUP(IFERROR(VLOOKUP(A24,'Cadastro Geral Campistas'!$A:$R,18,0),0),'Cadastro Geral Campistas'!$A:$R,2,""),""),TRIM(IF(AND(IFERROR(VLOOKUP(A24,'Cadastro Geral Campistas'!$A:$R,10,0),"")<>"",LOWER(TRIM(IFERROR(VLOOKUP(A24,'Cadastro Geral Campistas'!$A:$R,10,0),"")))<>"não",LOWER(TRIM(IFERROR(VLOOKUP(A24,'Cadastro Geral Campistas'!$A:$R,10,0),"")))<>"nao",LOWER(TRIM(IFERROR(VLOOKUP(A24,'Cadastro Geral Campistas'!$A:$R,10,0),"")))<>"0"),IFERROR(VLOOKUP(A24,'Cadastro Geral Campistas'!$A:$R,10,0),"")&IF(AND(IFERROR(VLOOKUP(A24,'Cadastro Geral Campistas'!$A:$R,15,0),"")<>"",LOWER(TRIM(IFERROR(VLOOKUP(A24,'Cadastro Geral Campistas'!$A:$R,15,0),"")))<>"não",LOWER(TRIM(IFERROR(VLOOKUP(A24,'Cadastro Geral Campistas'!$A:$R,15,0),"")))<>"nao",LOWER(TRIM(IFERROR(VLOOKUP(A24,'Cadastro Geral Campistas'!$A:$R,15,0),"")))<>"0")," | Alergia: "&IFERROR(VLOOKUP(A24,'Cadastro Geral Campistas'!$A:$R,15,0),""),""),IF(AND(IFERROR(VLOOKUP(A24,'Cadastro Geral Campistas'!$A:$R,15,0),"")<>"",LOWER(TRIM(IFERROR(VLOOKUP(A24,'Cadastro Geral Campistas'!$A:$R,15,0),"")))<>"não",LOWER(TRIM(IFERROR(VLOOKUP(A24,'Cadastro Geral Campistas'!$A:$R,15,0),"")))<>"nao",LOWER(TRIM(IFERROR(VLOOKUP(A24,'Cadastro Geral Campistas'!$A:$R,15,0),"")))<>"0"),"Alergia: "&IFERROR(VLOOKUP(A24,'Cadastro Geral Campistas'!$A:$R,15,0),""),"")))) | J24: =IFERROR(VLOOKUP(A24,'Cadastro Geral Campistas'!$A:$R,4,0),"")
A25: MÉDIA>>>>>>>>> | C25: =IFERROR(ROUND(AVERAGE(C9:C24),1),"") | E25: =IFERROR(ROUND(AVERAGE(E9:E24),1),"") | I25: =COUNTIF(J9:J24,"F")&" F | "&COUNTIF(J9:J24,"M")&" M"
I26: Sequências das dinâmicas:
I27: 1 - Casa do Pai
I28: 2 - Espelho
I29: 3 - Balanço
I30: 4 - Casa de Maria
I31: 5 - Salto da Fé
I32: 6 - Cabana
I33: 7 - Casa da Misericórdia
I34: 8 - Metrô
I35: 9 - Paredão
A36: Cor: Vermelha | E36: Tribo Rubem
A39: Anjos: | G39: Anjo Guardião:
A40: Helton | G40: Hugo Kisner
A41: Josiane Fiorini
A43: Ficha ✏️ | B43: Nome | C43: Peso | D43: Alt | E43: Idade | F43: Cidade | G43: Camiseta | H43: Celular | I43: ⚠️ Alerta / Observações | J43: Sexo
A44: 24 | B44: =IFERROR(VLOOKUP(A44,'Cadastro Geral Campistas'!$A:$R,2,0),"") | C44: =IFERROR(VLOOKUP(A44,'Cadastro Geral Campistas'!$A:$R,5,0),"") | D44: =IFERROR(VLOOKUP(A44,'Cadastro Geral Campistas'!$A:$R,6,0),"") | E44: =IFERROR(VLOOKUP(A44,'Cadastro Geral Campistas'!$A:$R,7,0),"") | F44: =IFERROR(VLOOKUP(A44,'Cadastro Geral Campistas'!$A:$R,9,0),"") | G44: =IFERROR(VLOOKUP(A44,'Cadastro Geral Campistas'!$A:$R,3,0),"") | H44: =IFERROR(VLOOKUP(A44,'Cadastro Geral Campistas'!$A:$R,8,0),"") | I44: =IF(AND(IFERROR(VLOOKUP(A44,'Cadastro Geral Campistas'!$A:$R,18,0),0)>0,COUNTIF($A$44:$A$59,IFERROR(VLOOKUP(A44,'Cadastro Geral Campistas'!$A:$R,18,0),0))>0),"⚠️ CONFLITO! Cônjuge na mesma tribo: "&IFERROR(VLOOKUP(IFERROR(VLOOKUP(A44,'Cadastro Geral Campistas'!$A:$R,18,0),0),'Cadastro Geral Campistas'!$A:$R,2,""),""),TRIM(IF(AND(IFERROR(VLOOKUP(A44,'Cadastro Geral Campistas'!$A:$R,10,0),"")<>"",LOWER(TRIM(IFERROR(VLOOKUP(A44,'Cadastro Geral Campistas'!$A:$R,10,0),"")))<>"não",LOWER(TRIM(IFERROR(VLOOKUP(A44,'Cadastro Geral Campistas'!$A:$R,10,0),"")))<>"nao",LOWER(TRIM(IFERROR(VLOOKUP(A44,'Cadastro Geral Campistas'!$A:$R,10,0),"")))<>"0"),IFERROR(VLOOKUP(A44,'Cadastro Geral Campistas'!$A:$R,10,0),"")&IF(AND(IFERROR(VLOOKUP(A44,'Cadastro Geral Campistas'!$A:$R,15,0),"")<>"",LOWER(TRIM(IFERROR(VLOOKUP(A44,'Cadastro Geral Campistas'!$A:$R,15,0),"")))<>"não",LOWER(TRIM(IFERROR(VLOOKUP(A44,'Cadastro Geral Campistas'!$A:$R,15,0),"")))<>"nao",LOWER(TRIM(IFERROR(VLOOKUP(A44,'Cadastro Geral Campistas'!$A:$R,15,0),"")))<>"0")," | Alergia: "&IFERROR(VLOOKUP(A44,'Cadastro Geral Campistas'!$A:$R,15,0),""),""),IF(AND(IFERROR(VLOOKUP(A44,'Cadastro Geral Campistas'!$A:$R,15,0),"")<>"",LOWER(TRIM(IFERROR(VLOOKUP(A44,'Cadastro Geral Campistas'!$A:$R,15,0),"")))<>"não",LOWER(TRIM(IFERROR(VLOOKUP(A44,'Cadastro Geral Campistas'!$A:$R,15,0),"")))<>"nao",LOWER(TRIM(IFERROR(VLOOKUP(A44,'Cadastro Geral Campistas'!$A:$R,15,0),"")))<>"0"),"Alergia: "&IFERROR(VLOOKUP(A44,'Cadastro Geral Campistas'!$A:$R,15,0),""),"")))) | J44: =IFERROR(VLOOKUP(A44,'Cadastro Geral Campistas'!$A:$R,4,0),"")
A45: 32 | B45: =IFERROR(VLOOKUP(A45,'Cadastro Geral Campistas'!$A:$R,2,0),"") | C45: =IFERROR(VLOOKUP(A45,'Cadastro Geral Campistas'!$A:$R,5,0),"") | D45: =IFERROR(VLOOKUP(A45,'Cadastro Geral Campistas'!$A:$R,6,0),"") | E45: =IFERROR(VLOOKUP(A45,'Cadastro Geral Campistas'!$A:$R,7,0),"") | F45: =IFERROR(VLOOKUP(A45,'Cadastro Geral Campistas'!$A:$R,9,0),"") | G45: =IFERROR(VLOOKUP(A45,'Cadastro Geral Campistas'!$A:$R,3,0),"") | H45: =IFERROR(VLOOKUP(A45,'Cadastro Geral Campistas'!$A:$R,8,0),"") | I45: =IF(AND(IFERROR(VLOOKUP(A45,'Cadastro Geral Campistas'!$A:$R,18,0),0)>0,COUNTIF($A$44:$A$59,IFERROR(VLOOKUP(A45,'Cadastro Geral Campistas'!$A:$R,18,0),0))>0),"⚠️ CONFLITO! Cônjuge na mesma tribo: "&IFERROR(VLOOKUP(IFERROR(VLOOKUP(A45,'Cadastro Geral Campistas'!$A:$R,18,0),0),'Cadastro Geral Campistas'!$A:$R,2,""),""),TRIM(IF(AND(IFERROR(VLOOKUP(A45,'Cadastro Geral Campistas'!$A:$R,10,0),"")<>"",LOWER(TRIM(IFERROR(VLOOKUP(A45,'Cadastro Geral Campistas'!$A:$R,10,0),"")))<>"não",LOWER(TRIM(IFERROR(VLOOKUP(A45,'Cadastro Geral Campistas'!$A:$R,10,0),"")))<>"nao",LOWER(TRIM(IFERROR(VLOOKUP(A45,'Cadastro Geral Campistas'!$A:$R,10,0),"")))<>"0"),IFERROR(VLOOKUP(A45,'Cadastro Geral Campistas'!$A:$R,10,0),"")&IF(AND(IFERROR(VLOOKUP(A45,'Cadastro Geral Campistas'!$A:$R,15,0),"")<>"",LOWER(TRIM(IFERROR(VLOOKUP(A45,'Cadastro Geral Campistas'!$A:$R,15,0),"")))<>"não",LOWER(TRIM(IFERROR(VLOOKUP(A45,'Cadastro Geral Campistas'!$A:$R,15,0),"")))<>"nao",LOWER(TRIM(IFERROR(VLOOKUP(A45,'Cadastro Geral Campistas'!$A:$R,15,0),"")))<>"0")," | Alergia: "&IFERROR(VLOOKUP(A45,'Cadastro Geral Campistas'!$A:$R,15,0),""),""),IF(AND(IFERROR(VLOOKUP(A45,'Cadastro Geral Campistas'!$A:$R,15,0),"")<>"",LOWER(TRIM(IFERROR(VLOOKUP(A45,'Cadastro Geral Campistas'!$A:$R,15,0),"")))<>"não",LOWER(TRIM(IFERROR(VLOOKUP(A45,'Cadastro Geral Campistas'!$A:$R,15,0),"")))<>"nao",LOWER(TRIM(IFERROR(VLOOKUP(A45,'Cadastro Geral Campistas'!$A:$R,15,0),"")))<>"0"),"Alergia: "&IFERROR(VLOOKUP(A45,'Cadastro Geral Campistas'!$A:$R,15,0),""),"")))) | J45: =IFERROR(VLOOKUP(A45,'Cadastro Geral Campistas'!$A:$R,4,0),"")
A46: 43 | B46: =IFERROR(VLOOKUP(A46,'Cadastro Geral Campistas'!$A:$R,2,0),"") | C46: =IFERROR(VLOOKUP(A46,'Cadastro Geral Campistas'!$A:$R,5,0),"") | D46: =IFERROR(VLOOKUP(A46,'Cadastro Geral Campistas'!$A:$R,6,0),"") | E46: =IFERROR(VLOOKUP(A46,'Cadastro Geral Campistas'!$A:$R,7,0),"") | F46: =IFERROR(VLOOKUP(A46,'Cadastro Geral Campistas'!$A:$R,9,0),"") | G46: =IFERROR(VLOOKUP(A46,'Cadastro Geral Campistas'!$A:$R,3,0),"") | H46: =IFERROR(VLOOKUP(A46,'Cadastro Geral Campistas'!$A:$R,8,0),"") | I46: =IF(AND(IFERROR(VLOOKUP(A46,'Cadastro Geral Campistas'!$A:$R,18,0),0)>0,COUNTIF($A$44:$A$59,IFERROR(VLOOKUP(A46,'Cadastro Geral Campistas'!$A:$R,18,0),0))>0),"⚠️ CONFLITO! Cônjuge na mesma tribo: "&IFERROR(VLOOKUP(IFERROR(VLOOKUP(A46,'Cadastro Geral Campistas'!$A:$R,18,0),0),'Cadastro Geral Campistas'!$A:$R,2,""),""),TRIM(IF(AND(IFERROR(VLOOKUP(A46,'Cadastro Geral Campistas'!$A:$R,10,0),"")<>"",LOWER(TRIM(IFERROR(VLOOKUP(A46,'Cadastro Geral Campistas'!$A:$R,10,0),"")))<>"não",LOWER(TRIM(IFERROR(VLOOKUP(A46,'Cadastro Geral Campistas'!$A:$R,10,0),"")))<>"nao",LOWER(TRIM(IFERROR(VLOOKUP(A46,'Cadastro Geral Campistas'!$A:$R,10,0),"")))<>"0"),IFERROR(VLOOKUP(A46,'Cadastro Geral Campistas'!$A:$R,10,0),"")&IF(AND(IFERROR(VLOOKUP(A46,'Cadastro Geral Campistas'!$A:$R,15,0),"")<>"",LOWER(TRIM(IFERROR(VLOOKUP(A46,'Cadastro Geral Campistas'!$A:$R,15,0),"")))<>"não",LOWER(TRIM(IFERROR(VLOOKUP(A46,'Cadastro Geral Campistas'!$A:$R,15,0),"")))<>"nao",LOWER(TRIM(IFERROR(VLOOKUP(A46,'Cadastro Geral Campistas'!$A:$R,15,0),"")))<>"0")," | Alergia: "&IFERROR(VLOOKUP(A46,'Cadastro Geral Campistas'!$A:$R,15,0),""),""),IF(AND(IFERROR(VLOOKUP(A46,'Cadastro Geral Campistas'!$A:$R,15,0),"")<>"",LOWER(TRIM(IFERROR(VLOOKUP(A46,'Cadastro Geral Campistas'!$A:$R,15,0),"")))<>"não",LOWER(TRIM(IFERROR(VLOOKUP(A46,'Cadastro Geral Campistas'!$A:$R,15,0),"")))<>"nao",LOWER(TRIM(IFERROR(VLOOKUP(A46,'Cadastro Geral Campistas'!$A:$R,15,0),"")))<>"0"),"Alergia: "&IFERROR(VLOOKUP(A46,'Cadastro Geral Campistas'!$A:$R,15,0),""),"")))) | J46: =IFERROR(VLOOKUP(A46,'Cadastro Geral Campistas'!$A:$R,4,0),"")
A47: 73 | B47: =IFERROR(VLOOKUP(A47,'Cadastro Geral Campistas'!$A:$R,2,0),"") | C47: =IFERROR(VLOOKUP(A47,'Cadastro Geral Campistas'!$A:$R,5,0),"") | D47: =IFERROR(VLOOKUP(A47,'Cadastro Geral Campistas'!$A:$R,6,0),"") | E47: =IFERROR(VLOOKUP(A47,'Cadastro Geral Campistas'!$A:$R,7,0),"") | F47: =IFERROR(VLOOKUP(A47,'Cadastro Geral Campistas'!$A:$R,9,0),"") | G47: =IFERROR(VLOOKUP(A47,'Cadastro Geral Campistas'!$A:$R,3,0),"") | H47: =IFERROR(VLOOKUP(A47,'Cadastro Geral Campistas'!$A:$R,8,0),"") | I47: =IF(AND(IFERROR(VLOOKUP(A47,'Cadastro Geral Campistas'!$A:$R,18,0),0)>0,COUNTIF($A$44:$A$59,IFERROR(VLOOKUP(A47,'Cadastro Geral Campistas'!$A:$R,18,0),0))>0),"⚠️ CONFLITO! Cônjuge na mesma tribo: "&IFERROR(VLOOKUP(IFERROR(VLOOKUP(A47,'Cadastro Geral Campistas'!$A:$R,18,0),0),'Cadastro Geral Campistas'!$A:$R,2,""),""),TRIM(IF(AND(IFERROR(VLOOKUP(A47,'Cadastro Geral Campistas'!$A:$R,10,0),"")<>"",LOWER(TRIM(IFERROR(VLOOKUP(A47,'Cadastro Geral Campistas'!$A:$R,10,0),"")))<>"não",LOWER(TRIM(IFERROR(VLOOKUP(A47,'Cadastro Geral Campistas'!$A:$R,10,0),"")))<>"nao",LOWER(TRIM(IFERROR(VLOOKUP(A47,'Cadastro Geral Campistas'!$A:$R,10,0),"")))<>"0"),IFERROR(VLOOKUP(A47,'Cadastro Geral Campistas'!$A:$R,10,0),"")&IF(AND(IFERROR(VLOOKUP(A47,'Cadastro Geral Campistas'!$A:$R,15,0),"")<>"",LOWER(TRIM(IFERROR(VLOOKUP(A47,'Cadastro Geral Campistas'!$A:$R,15,0),"")))<>"não",LOWER(TRIM(IFERROR(VLOOKUP(A47,'Cadastro Geral Campistas'!$A:$R,15,0),"")))<>"nao",LOWER(TRIM(IFERROR(VLOOKUP(A47,'Cadastro Geral Campistas'!$A:$R,15,0),"")))<>"0")," | Alergia: "&IFERROR(VLOOKUP(A47,'Cadastro Geral Campistas'!$A:$R,15,0),""),""),IF(AND(IFERROR(VLOOKUP(A47,'Cadastro Geral Campistas'!$A:$R,15,0),"")<>"",LOWER(TRIM(IFERROR(VLOOKUP(A47,'Cadastro Geral Campistas'!$A:$R,15,0),"")))<>"não",LOWER(TRIM(IFERROR(VLOOKUP(A47,'Cadastro Geral Campistas'!$A:$R,15,0),"")))<>"nao",LOWER(TRIM(IFERROR(VLOOKUP(A47,'Cadastro Geral Campistas'!$A:$R,15,0),"")))<>"0"),"Alergia: "&IFERROR(VLOOKUP(A47,'Cadastro Geral Campistas'!$A:$R,15,0),""),"")))) | J47: =IFERROR(VLOOKUP(A47,'Cadastro Geral Campistas'!$A:$R,4,0),"")
A48: 76 | B48: =IFERROR(VLOOKUP(A48,'Cadastro Geral Campistas'!$A:$R,2,0),"") | C48: =IFERROR(VLOOKUP(A48,'Cadastro Geral Campistas'!$A:$R,5,0),"") | D48: =IFERROR(VLOOKUP(A48,'Cadastro Geral Campistas'!$A:$R,6,0),"") | E48: =IFERROR(VLOOKUP(A48,'Cadastro Geral Campistas'!$A:$R,7,0),"") | F48: =IFERROR(VLOOKUP(A48,'Cadastro Geral Campistas'!$A:$R,9,0),"") | G48: =IFERROR(VLOOKUP(A48,'Cadastro Geral Campistas'!$A:$R,3,0),"") | H48: =IFERROR(VLOOKUP(A48,'Cadastro Geral Campistas'!$A:$R,8,0),"") | I48: =IF(AND(IFERROR(VLOOKUP(A48,'Cadastro Geral Campistas'!$A:$R,18,0),0)>0,COUNTIF($A$44:$A$59,IFERROR(VLOOKUP(A48,'Cadastro Geral Campistas'!$A:$R,18,0),0))>0),"⚠️ CONFLITO! Cônjuge na mesma tribo: "&IFERROR(VLOOKUP(IFERROR(VLOOKUP(A48,'Cadastro Geral Campistas'!$A:$R,18,0),0),'Cadastro Geral Campistas'!$A:$R,2,""),""),TRIM(IF(AND(IFERROR(VLOOKUP(A48,'Cadastro Geral Campistas'!$A:$R,10,0),"")<>"",LOWER(TRIM(IFERROR(VLOOKUP(A48,'Cadastro Geral Campistas'!$A:$R,10,0),"")))<>"não",LOWER(TRIM(IFERROR(VLOOKUP(A48,'Cadastro Geral Campistas'!$A:$R,10,0),"")))<>"nao",LOWER(TRIM(IFERROR(VLOOKUP(A48,'Cadastro Geral Campistas'!$A:$R,10,0),"")))<>"0"),IFERROR(VLOOKUP(A48,'Cadastro Geral Campistas'!$A:$R,10,0),"")&IF(AND(IFERROR(VLOOKUP(A48,'Cadastro Geral Campistas'!$A:$R,15,0),"")<>"",LOWER(TRIM(IFERROR(VLOOKUP(A48,'Cadastro Geral Campistas'!$A:$R,15,0),"")))<>"não",LOWER(TRIM(IFERROR(VLOOKUP(A48,'Cadastro Geral Campistas'!$A:$R,15,0),"")))<>"nao",LOWER(TRIM(IFERROR(VLOOKUP(A48,'Cadastro Geral Campistas'!$A:$R,15,0),"")))<>"0")," | Alergia: "&IFERROR(VLOOKUP(A48,'Cadastro Geral Campistas'!$A:$R,15,0),""),""),IF(AND(IFERROR(VLOOKUP(A48,'Cadastro Geral Campistas'!$A:$R,15,0),"")<>"",LOWER(TRIM(IFERROR(VLOOKUP(A48,'Cadastro Geral Campistas'!$A:$R,15,0),"")))<>"não",LOWER(TRIM(IFERROR(VLOOKUP(A48,'Cadastro Geral Campistas'!$A:$R,15,0),"")))<>"nao",LOWER(TRIM(IFERROR(VLOOKUP(A48,'Cadastro Geral Campistas'!$A:$R,15,0),"")))<>"0"),"Alergia: "&IFERROR(VLOOKUP(A48,'Cadastro Geral Campistas'!$A:$R,15,0),""),"")))) | J48: =IFERROR(VLOOKUP(A48,'Cadastro Geral Campistas'!$A:$R,4,0),"")
A49: 80 | B49: =IFERROR(VLOOKUP(A49,'Cadastro Geral Campistas'!$A:$R,2,0),"") | C49: =IFERROR(VLOOKUP(A49,'Cadastro Geral Campistas'!$A:$R,5,0),"") | D49: =IFERROR(VLOOKUP(A49,'Cadastro Geral Campistas'!$A:$R,6,0),"") | E49: =IFERROR(VLOOKUP(A49,'Cadastro Geral Campistas'!$A:$R,7,0),"") | F49: =IFERROR(VLOOKUP(A49,'Cadastro Geral Campistas'!$A:$R,9,0),"") | G49: =IFERROR(VLOOKUP(A49,'Cadastro Geral Campistas'!$A:$R,3,0),"") | H49: =IFERROR(VLOOKUP(A49,'Cadastro Geral Campistas'!$A:$R,8,0),"") | I49: =IF(AND(IFERROR(VLOOKUP(A49,'Cadastro Geral Campistas'!$A:$R,18,0),0)>0,COUNTIF($A$44:$A$59,IFERROR(VLOOKUP(A49,'Cadastro Geral Campistas'!$A:$R,18,0),0))>0),"⚠️ CONFLITO! Cônjuge na mesma tribo: "&IFERROR(VLOOKUP(IFERROR(VLOOKUP(A49,'Cadastro Geral Campistas'!$A:$R,18,0),0),'Cadastro Geral Campistas'!$A:$R,2,""),""),TRIM(IF(AND(IFERROR(VLOOKUP(A49,'Cadastro Geral Campistas'!$A:$R,10,0),"")<>"",LOWER(TRIM(IFERROR(VLOOKUP(A49,'Cadastro Geral Campistas'!$A:$R,10,0),"")))<>"não",LOWER(TRIM(IFERROR(VLOOKUP(A49,'Cadastro Geral Campistas'!$A:$R,10,0),"")))<>"nao",LOWER(TRIM(IFERROR(VLOOKUP(A49,'Cadastro Geral Campistas'!$A:$R,10,0),"")))<>"0"),IFERROR(VLOOKUP(A49,'Cadastro Geral Campistas'!$A:$R,10,0),"")&IF(AND(IFERROR(VLOOKUP(A49,'Cadastro Geral Campistas'!$A:$R,15,0),"")<>"",LOWER(TRIM(IFERROR(VLOOKUP(A49,'Cadastro Geral Campistas'!$A:$R,15,0),"")))<>"não",LOWER(TRIM(IFERROR(VLOOKUP(A49,'Cadastro Geral Campistas'!$A:$R,15,0),"")))<>"nao",LOWER(TRIM(IFERROR(VLOOKUP(A49,'Cadastro Geral Campistas'!$A:$R,15,0),"")))<>"0")," | Alergia: "&IFERROR(VLOOKUP(A49,'Cadastro Geral Campistas'!$A:$R,15,0),""),""),IF(AND(IFERROR(VLOOKUP(A49,'Cadastro Geral Campistas'!$A:$R,15,0),"")<>"",LOWER(TRIM(IFERROR(VLOOKUP(A49,'Cadastro Geral Campistas'!$A:$R,15,0),"")))<>"não",LOWER(TRIM(IFERROR(VLOOKUP(A49,'Cadastro Geral Campistas'!$A:$R,15,0),"")))<>"nao",LOWER(TRIM(IFERROR(VLOOKUP(A49,'Cadastro Geral Campistas'!$A:$R,15,0),"")))<>"0"),"Alergia: "&IFERROR(VLOOKUP(A49,'Cadastro Geral Campistas'!$A:$R,15,0),""),"")))) | J49: =IFERROR(VLOOKUP(A49,'Cadastro Geral Campistas'!$A:$R,4,0),"")
...

Sheet Relatorio Chamada Onibus
A1: =CONCATENATE("ÔNIBUS 01 — ",COUNTA(A3:A38)," campistas")
A2: FC ✏️ | B2: CAMPISTAS | C2: CIDADE | D2: TRIBO | E2: FONE: | F2: CELULAR | G2: EMBARCOU ✅
A3: 3 | B3: =IFERROR(VLOOKUP(A3,'Cadastro Geral Campistas'!$A:$R,2,0),"") | C3: =IFERROR(VLOOKUP(A3,'Cadastro Geral Campistas'!$A:$R,9,0),"") | D3: =IFERROR(VLOOKUP(A3,'Cadastro Geral Campistas'!$A:$R,17,0),"") | F3: =IFERROR(VLOOKUP(A3,'Cadastro Geral Campistas'!$A:$R,8,0),"")
A4: 100 | B4: =IFERROR(VLOOKUP(A4,'Cadastro Geral Campistas'!$A:$R,2,0),"") | C4: =IFERROR(VLOOKUP(A4,'Cadastro Geral Campistas'!$A:$R,9,0),"") | D4: =IFERROR(VLOOKUP(A4,'Cadastro Geral Campistas'!$A:$R,17,0),"") | F4: =IFERROR(VLOOKUP(A4,'Cadastro Geral Campistas'!$A:$R,8,0),"")
A5: 19 | B5: =IFERROR(VLOOKUP(A5,'Cadastro Geral Campistas'!$A:$R,2,0),"") | C5: =IFERROR(VLOOKUP(A5,'Cadastro Geral Campistas'!$A:$R,9,0),"") | D5: =IFERROR(VLOOKUP(A5,'Cadastro Geral Campistas'!$A:$R,17,0),"") | F5: =IFERROR(VLOOKUP(A5,'Cadastro Geral Campistas'!$A:$R,8,0),"")
A6: 71 | B6: =IFERROR(VLOOKUP(A6,'Cadastro Geral Campistas'!$A:$R,2,0),"") | C6: =IFERROR(VLOOKUP(A6,'Cadastro Geral Campistas'!$A:$R,9,0),"") | D6: =IFERROR(VLOOKUP(A6,'Cadastro Geral Campistas'!$A:$R,17,0),"") | F6: =IFERROR(VLOOKUP(A6,'Cadastro Geral Campistas'!$A:$R,8,0),"")
A7: 91 | B7: =IFERROR(VLOOKUP(A7,'Cadastro Geral Campistas'!$A:$R,2,0),"") | C7: =IFERROR(VLOOKUP(A7,'Cadastro Geral Campistas'!$A:$R,9,0),"") | D7: =IFERROR(VLOOKUP(A7,'Cadastro Geral Campistas'!$A:$R,17,0),"") | F7: =IFERROR(VLOOKUP(A7,'Cadastro Geral Campistas'!$A:$R,8,0),"")
A8: 137 | B8: =IFERROR(VLOOKUP(A8,'Cadastro Geral Campistas'!$A:$R,2,0),"") | C8: =IFERROR(VLOOKUP(A8,'Cadastro Geral Campistas'!$A:$R,9,0),"") | D8: =IFERROR(VLOOKUP(A8,'Cadastro Geral Campistas'!$A:$R,17,0),"") | F8: =IFERROR(VLOOKUP(A8,'Cadastro Geral Campistas'!$A:$R,8,0),"")
A9: 6 | B9: =IFERROR(VLOOKUP(A9,'Cadastro Geral Campistas'!$A:$R,2,0),"") | C9: =IFERROR(VLOOKUP(A9,'Cadastro Geral Campistas'!$A:$R,9,0),"") | D9: =IFERROR(VLOOKUP(A9,'Cadastro Geral Campistas'!$A:$R,17,0),"") | F9: =IFERROR(VLOOKUP(A9,'Cadastro Geral Campistas'!$A:$R,8,0),"")
A10: 13 | B10: =IFERROR(VLOOKUP(A10,'Cadastro Geral Campistas'!$A:$R,2,0),"") | C10: =IFERROR(VLOOKUP(A10,'Cadastro Geral Campistas'!$A:$R,9,0),"") | D10: =IFERROR(VLOOKUP(A10,'Cadastro Geral Campistas'!$A:$R,17,0),"") | F10: =IFERROR(VLOOKUP(A10,'Cadastro Geral Campistas'!$A:$R,8,0),"")
A11: 18 | B11: =IFERROR(VLOOKUP(A11,'Cadastro Geral Campistas'!$A:$R,2,0),"") | C11: =IFERROR(VLOOKUP(A11,'Cadastro Geral Campistas'!$A:$R,9,0),"") | D11: =IFERROR(VLOOKUP(A11,'Cadastro Geral Campistas'!$A:$R,17,0),"") | F11: =IFERROR(VLOOKUP(A11,'Cadastro Geral Campistas'!$A:$R,8,0),"")
A12: 24 | B12: =IFERROR(VLOOKUP(A12,'Cadastro Geral Campistas'!$A:$R,2,0),"") | C12: =IFERROR(VLOOKUP(A12,'Cadastro Geral Campistas'!$A:$R,9,0),"") | D12: =IFERROR(VLOOKUP(A12,'Cadastro Geral Campistas'!$A:$R,17,0),"") | F12: =IFERROR(VLOOKUP(A12,'Cadastro Geral Campistas'!$A:$R,8,0),"")
A13: 29 | B13: =IFERROR(VLOOKUP(A13,'Cadastro Geral Campistas'!$A:$R,2,0),"") | C13: =IFERROR(VLOOKUP(A13,'Cadastro Geral Campistas'!$A:$R,9,0),"") | D13: =IFERROR(VLOOKUP(A13,'Cadastro Geral Campistas'!$A:$R,17,0),"") | F13: =IFERROR(VLOOKUP(A13,'Cadastro Geral Campistas'!$A:$R,8,0),"")
A14: 35 | B14: =IFERROR(VLOOKUP(A14,'Cadastro Geral Campistas'!$A:$R,2,0),"") | C14: =IFERROR(VLOOKUP(A14,'Cadastro Geral Campistas'!$A:$R,9,0),"") | D14: =IFERROR(VLOOKUP(A14,'Cadastro Geral Campistas'!$A:$R,17,0),"") | F14: =IFERROR(VLOOKUP(A14,'Cadastro Geral Campistas'!$A:$R,8,0),"")
... A38: 141 | B38: =IFERROR(VLOOKUP(A38,'Cadastro Geral Campistas'!$A:$R,2,0),"") | C38: =IFERROR(VLOOKUP(A38,'Cadastro Geral Campistas'!$A:$R,9,0),"") | D38: =IFERROR(VLOOKUP(A38,'Cadastro Geral Campistas'!$A:$R,17,0),"") | F38: =IFERROR(VLOOKUP(A38,'Cadastro Geral Campistas'!$A:$R,8,0),"")
A40: =CONCATENATE("ÔNIBUS 02 — ",COUNTA(A42:A77)," campistas")
A41: FC ✏️ | B41: CAMPISTAS | C41: CIDADE | D41: TRIBO | E41: FONE: | F41: CELULAR | G41: EMBARCOU ✅
A42: 7 | B42: =IFERROR(VLOOKUP(A42,'Cadastro Geral Campistas'!$A:$R,2,0),"") | C42: =IFERROR(VLOOKUP(A42,'Cadastro Geral Campistas'!$A:$R,9,0),"") | D42: =IFERROR(VLOOKUP(A42,'Cadastro Geral Campistas'!$A:$R,17,0),"") | F42: =IFERROR(VLOOKUP(A42,'Cadastro Geral Campistas'!$A:$R,8,0),"")
A43: 16 | B43: =IFERROR(VLOOKUP(A43,'Cadastro Geral Campistas'!$A:$R,2,0),"") | C43: =IFERROR(VLOOKUP(A43,'Cadastro Geral Campistas'!$A:$R,9,0),"") | D43: =IFERROR(VLOOKUP(A43,'Cadastro Geral Campistas'!$A:$R,17,0),"") | F43: =IFERROR(VLOOKUP(A43,'Cadastro Geral Campistas'!$A:$R,8,0),"")
A44: 21 | B44: =IFERROR(VLOOKUP(A44,'Cadastro Geral Campistas'!$A:$R,2,0),"") | C44: =IFERROR(VLOOKUP(A44,'Cadastro Geral Campistas'!$A:$R,9,0),"") | D44: =IFERROR(VLOOKUP(A44,'Cadastro Geral Campistas'!$A:$R,17,0),"") | F44: =IFERROR(VLOOKUP(A44,'Cadastro Geral Campistas'!$A:$R,8,0),"")
A45: 105 | B45: =IFERROR(VLOOKUP(A45,'Cadastro Geral Campistas'!$A:$R,2,0),"") | C45: =IFERROR(VLOOKUP(A45,'Cadastro Geral Campistas'!$A:$R,9,0),"") | D45: =IFERROR(VLOOKUP(A45,'Cadastro Geral Campistas'!$A:$R,17,0),"") | F45: =IFERROR(VLOOKUP(A45,'Cadastro Geral Campistas'!$A:$R,8,0),"")
A46: 93 | B46: =IFERROR(VLOOKUP(A46,'Cadastro Geral Campistas'!$A:$R,2,0),"") | C46: =IFERROR(VLOOKUP(A46,'Cadastro Geral Campistas'!$A:$R,9,0),"") | D46: =IFERROR(VLOOKUP(A46,'Cadastro Geral Campistas'!$A:$R,17,0),"") | F46: =IFERROR(VLOOKUP(A46,'Cadastro Geral Campistas'!$A:$R,8,0),"")
A47: 119 | B47: =IFERROR(VLOOKUP(A47,'Cadastro Geral Campistas'!$A:$R,2,0),"") | C47: =IFERROR(VLOOKUP(A47,'Cadastro Geral Campistas'!$A:$R,9,0),"") | D47: =IFERROR(VLOOKUP(A47,'Cadastro Geral Campistas'!$A:$R,17,0),"") | F47: =IFERROR(VLOOKUP(A47,'Cadastro Geral Campistas'!$A:$R,8,0),"")
A48: 9 | B48: =IFERROR(VLOOKUP(A48,'Cadastro Geral Campistas'!$A:$R,2,0),"") | C48: =IFERROR(VLOOKUP(A48,'Cadastro Geral Campistas'!$A:$R,9,0),"") | D48: =IFERROR(VLOOKUP(A48,'Cadastro Geral Campistas'!$A:$R,17,0),"") | F48: =IFERROR(VLOOKUP(A48,'Cadastro Geral Campistas'!$A:$R,8,0),"")
A49: 14 | B49: =IFERROR(VLOOKUP(A49,'Cadastro Geral Campistas'!$A:$R,2,0),"") | C49: =IFERROR(VLOOKUP(A49,'Cadastro Geral Campistas'!$A:$R,9,0),"") | D49: =IFERROR(VLOOKUP(A49,'Cadastro Geral Campistas'!$A:$R,17,0),"") | F49: =IFERROR(VLOOKUP(A49,'Cadastro Geral Campistas'!$A:$R,8,0),"")
A50: 20 | B50: =IFERROR(VLOOKUP(A50,'Cadastro Geral Campistas'!$A:$R,2,0),"") | C50: =IFERROR(VLOOKUP(A50,'Cadastro Geral Campistas'!$A:$R,9,0),"") | D50: =IFERROR(VLOOKUP(A50,'Cadastro Geral Campistas'!$A:$R,17,0),"") | F50: =IFERROR(VLOOKUP(A50,'Cadastro Geral Campistas'!$A:$R,8,0),"")
A51: 25 | B51: =IFERROR(VLOOKUP(A51,'Cadastro Geral Campistas'!$A:$R,2,0),"") | C51: =IFERROR(VLOOKUP(A51,'Cadastro Geral Campistas'!$A:$R,9,0),"") | D51: =IFERROR(VLOOKUP(A51,'Cadastro Geral Campistas'!$A:$R,17,0),"") | F51: =IFERROR(VLOOKUP(A51,'Cadastro Geral Campistas'!$A:$R,8,0),"")
A52: 30 | B52: =IFERROR(VLOOKUP(A52,'Cadastro Geral Campistas'!$A:$R,2,0),"") | C52: =IFERROR(VLOOKUP(A52,'Cadastro Geral Campistas'!$A:$R,9,0),"") | D52: =IFERROR(VLOOKUP(A52,'Cadastro Geral Campistas'!$A:$R,17,0),"") | F52: =IFERROR(VLOOKUP(A52,'Cadastro Geral Campistas'!$A:$R,8,0),"")
A53: 36 | B53: =IFERROR(VLOOKUP(A53,'Cadastro Geral Campistas'!$A:$R,2,0),"") | C53: =IFERROR(VLOOKUP(A53,'Cadastro Geral Campistas'!$A:$R,9,0),"") | D53: =IFERROR(VLOOKUP(A53,'Cadastro Geral Campistas'!$A:$R,17,0),"") | F53: =IFERROR(VLOOKUP(A53,'Cadastro Geral Campistas'!$A:$R,8,0),"")
... A77: 142 | B77: =IFERROR(VLOOKUP(A77,'Cadastro Geral Campistas'!$A:$R,2,0),"") | C77: =IFERROR(VLOOKUP(A77,'Cadastro Geral Campistas'!$A:$R,9,0),"") | D77: =IFERROR(VLOOKUP(A77,'Cadastro Geral Campistas'!$A:$R,17,0),"") | F77: =IFERROR(VLOOKUP(A77,'Cadastro Geral Campistas'!$A:$R,8,0),"")
A79: =CONCATENATE("ÔNIBUS 03 — ",COUNTA(A81:A116)," campistas")
